Workbook
Name Fin_E: #REF!
Name Fin_E: #REF!
Name Fin_E: #REF!
Name Fin_ER: #REF!
Name Fin_ER: #REF!
Name Fin_ER: #REF!
Name Fin_N: #REF!
Name Fin_N: #REF!
Name Fin_N: #REF!
Name Fin_P: #REF!
Name Fin_R: #REF!
Name Fin_R: #REF!
Name Fin_R: #REF!
Name Inicio_E: #REF!
Name Inicio_E: #REF!
Name Inicio_E: #REF!
Name Inicio_ER: #REF!
Name Inicio_ER: #REF!
Name Inicio_ER: #REF!
Name Inicio_N: #REF!
Name Inicio_N: #REF!
Name Inicio_N: #REF!
Name Inicio_P: #REF!
Name Inicio_R: #REF!
Name Inicio_R: #REF!
Name Inicio_R: #REF!

Sheet ✈️
B3: Hollywood Planet 23 de septiembre al 28 de septiembre
C4: 🏨 | D4: 🏖️ | E4: 🚕 | F4: 🏄🏻🍾 | G4: 🛫 | H4: 🧳 | I4: 💺 | J4: 😡 | K4: Est | L4: Av | M4: Tt
B5: Miguel pa 👨🏻‍🦳 | C5: 12536.67 | D5: 152 | E5: 500 | F5: 200 | G5: 1400 | H5: 553 | I5: =330+290 -> 620 | J5: =4125/4 -> 1031.25 | K5: =SUM(C5:F5) -> 13388.67 | L5: =SUM(G5:J5) -> 3604.25 | M5: =SUM(C5:J5) -> 16992.92
B6: Lechon 🐷 | C6: 0 | E6: 500 | F6: 200 | G6: 1400 | H6: 553 | I6: =330+290 -> 620 | J6: =4125/4 -> 1031.25 | K6: =SUM(C6:F6) -> 700 | L6: =SUM(G6:J6) -> 3604.25 | M6: =SUM(C6:J6) -> 4304.25
B7: Sam 💖 | C7: 12536.67 | D7: 152 | E7: 500 | F7: 1000 | G7: 1400 | H7: 553 | I7: =330+290 -> 620 | J7: =4125/4 -> 1031.25 | K7: =SUM(C7:F7) -> 14188.67 | L7: =SUM(G7:J7) -> 3604.25 | M7: =SUM(C7:J7) -> 17792.92
B8: Franky 💀 | C8: 12536.67 | D8: 152 | E8: 500 | F8: 1000 | G8: 1400 | H8: 553 | I8: =330+290 -> 620 | J8: =4125/4 -> 1031.25 | K8: =SUM(C8:F8) -> 14188.67 | L8: =SUM(G8:J8) -> 3604.25 | M8: =SUM(C8:J8) -> 17792.92
C9: =SUM(C5:C8) -> 37610.01 | D9: =SUM(D5:D8) -> 456 | E9: =SUM(E5:E8) -> 2000 | F9: =SUM(F5:F8) -> 2400 | G9: =SUM(G5:G8) -> 5600 | H9: =SUM(H5:H8) -> 2212 | I9: =SUM(I5:I8) -> 2480 | J9: =SUM(J5:J8) -> 4125 | K9: =SUM(C9:F9) -> 42466.01 | L9: =SUM(G9:J9) -> 14417 | M9: =SUM(M5:M8) -> 56883.01
D11: Yo | E11: TT
C12: 01 de jun | D12: =SUM(G9:I9) -> 10292 | E12: =SUM(G9:I9) -> 10292
C13: 16 de ago | D13: =J9 -> 4125 | E13: =J9 -> 4125
C14: 16 de sept | D14: =SUM(C6:C8) -> 25073.34 | E14: =SUM(C5:C8) -> 37610.01
C15: 23 de sept | D15: =SUM(D6:F8) -> 4004 | E15: =SUM(D5:F8) -> 4856

Sheet Ingresos
A1: Fecha | B1: Inicio | C1: Fin | D1: DíaP | E1: NQ | F1: Tipo | G1: Estatus | H1: Normal | I1: Complementaria | J1: Aguinaldo | K1: Cred
A2: 46143 | B2: 46143 | C2: 46157 | D2: 1 | E2: Q4 | F2: Ingresos | G2: Pagado | H2: 10557 | I2: 4443 | K2: 3400
A3: 46144 | B3: 46143 | C3: 46157 | D3: 0 | E3: Q4
A4: 46145 | B4: 46143 | C4: 46157 | D4: 0 | E4: Q4
A5: 46146 | B5: 46143 | C5: 46157 | D5: 0 | E5: Q4
A6: 46147 | B6: 46143 | C6: 46157 | D6: 0 | E6: Q4
A7: 46148 | B7: 46143 | C7: 46157 | D7: 0 | E7: Q4
A8: 46149 | B8: 46143 | C8: 46157 | D8: 0 | E8: Q4
A9: 46150 | B9: 46143 | C9: 46157 | D9: 0 | E9: Q4
A10: 46151 | B10: 46143 | C10: 46157 | D10: 0 | E10: Q4
A11: 46152 | B11: 46143 | C11: 46157 | D11: 0 | E11: Q4
A12: 46153 | B12: 46143 | C12: 46157 | D12: 0 | E12: Q4
A13: 46154 | B13: 46143 | C13: 46157 | D13: 0 | E13: Q4
A14: 46155 | B14: 46143 | C14: 46157 | D14: 0 | E14: Q4
... A16: 46157 | B16: 46143 | C16: 46157 | D16: 0 | E16: Q4
A17: 46158 | B17: 46158 | C17: 46173 | D17: 1 | E17: Q5 | F17: Ingresos | G17: Pagado | H17: 10557 | I17: 4443 | K17: 6000
A18: 46159 | B18: 46158 | C18: 46173 | D18: 0 | E18: Q5
A19: 46160 | B19: 46158 | C19: 46173 | D19: 0 | E19: Q5
A20: 46161 | B20: 46158 | C20: 46173 | D20: 0 | E20: Q5
A21: 46162 | B21: 46158 | C21: 46173 | D21: 0 | E21: Q5
A22: 46163 | B22: 46158 | C22: 46173 | D22: 0 | E22: Q5
A23: 46164 | B23: 46158 | C23: 46173 | D23: 0 | E23: Q5
A24: 46165 | B24: 46158 | C24: 46173 | D24: 0 | E24: Q5
A25: 46166 | B25: 46158 | C25: 46173 | D25: 0 | E25: Q5
A26: 46167 | B26: 46158 | C26: 46173 | D26: 0 | E26: Q5
A27: 46168 | B27: 46158 | C27: 46173 | D27: 0 | E27: Q5
A28: 46169 | B28: 46158 | C28: 46173 | D28: 0 | E28: Q5
A29: 46170 | B29: 46158 | C29: 46173 | D29: 0 | E29: Q5
... A32: 46173 | B32: 46158 | C32: 46173 | D32: 0 | E32: Q5
A33: 46174 | B33: 46174 | C33: 46188 | D33: 1 | E33: Q6 | F33: Ingresos | G33: Pagado | H33: 10557 | I33: 4443
A34: 46175 | B34: 46174 | C34: 46188 | D34: 0 | E34: Q6
A35: 46176 | B35: 46174 | C35: 46188 | D35: 0 | E35: Q6
A36: 46177 | B36: 46174 | C36: 46188 | D36: 0 | E36: Q6
A37: 46178 | B37: 46174 | C37: 46188 | D37: 0 | E37: Q6
A38: 46179 | B38: 46174 | C38: 46188 | D38: 0 | E38: Q6
A39: 46180 | B39: 46174 | C39: 46188 | D39: 0 | E39: Q6
A40: 46181 | B40: 46174 | C40: 46188 | D40: 0 | E40: Q6
A41: 46182 | B41: 46174 | C41: 46188 | D41: 0 | E41: Q6
A42: 46183 | B42: 46174 | C42: 46188 | D42: 0 | E42: Q6
A43: 46184 | B43: 46174 | C43: 46188 | D43: 0 | E43: Q6
...

Sheet Gasto Real
A1: Fecha | B1: Inicio | C1: Fin | D1: DíaP | E1: NQ | F1: Tipo | G1: Estatus | H1: Transporte | I1: SADM | J1: IZZI | K1: Movistar | L1: Netflix | M1: Naturgy | N1: CFE | O1: Despensa | P1: Otros gastos | Q1: Uber one | R1: Didi+ | S1: Prime | T1: U2B Premium
A2: 46143 | B2: 46143 | C2: 46157 | D2: 1 | E2: Q4 | F2: Gasto | G2: Real | H2: 0 | N2: =231+283 -> 514 | O2: =408.76+868.91 -> 1277.67 | P2: 4228.18 | R2: 70 | S2: 70 | Y2: =SUM(Gasto_real[[#This Row],[Transporte]:[U2B Premium]]) -> 6159.85
A3: 46144 | B3: 46143 | C3: 46157 | D3: 0 | E3: Q4 | F3: Gasto | G3: Real | H3: =16.6+9.9+8.5+48.58 -> 83.58 | P3: 2000 | Y3: =SUM(Gasto_real[[#This Row],[Transporte]:[U2B Premium]]) -> 2083.58
A4: 46145 | B4: 46143 | C4: 46157 | D4: 0 | E4: Q4 | F4: Gasto | G4: Real | Y4: =SUM(Gasto_real[[#This Row],[Transporte]:[U2B Premium]]) -> 0
A5: 46146 | B5: 46143 | C5: 46157 | D5: 0 | E5: Q4 | F5: Gasto | G5: Real | H5: =16.6+9.9+8.5+69 -> 104 | Y5: =SUM(Gasto_real[[#This Row],[Transporte]:[U2B Premium]]) -> 104
A6: 46147 | B6: 46143 | C6: 46157 | D6: 0 | E6: Q4 | F6: Gasto | G6: Real | H6: =16.6+9.9+8.5+47.82 -> 82.82 | Y6: =SUM(Gasto_real[[#This Row],[Transporte]:[U2B Premium]]) -> 82.82
A7: 46148 | B7: 46143 | C7: 46157 | D7: 0 | E7: Q4 | F7: Gasto | G7: Real | H7: =16.6+9.9+8.5+56 -> 91 | Y7: =SUM(Gasto_real[[#This Row],[Transporte]:[U2B Premium]]) -> 91
A8: 46149 | B8: 46143 | C8: 46157 | D8: 0 | E8: Q4 | F8: Gasto | G8: Real | H8: =16.6+9.9+8.5+52 -> 87 | Y8: =SUM(Gasto_real[[#This Row],[Transporte]:[U2B Premium]]) -> 87
A9: 46150 | B9: 46143 | C9: 46157 | D9: 2 | E9: Q4 | F9: Gasto | G9: Real | H9: =16.6+9.9+8.5+56 -> 91 | Y9: =SUM(Gasto_real[[#This Row],[Transporte]:[U2B Premium]]) -> 91
A10: 46151 | B10: 46143 | C10: 46157 | D10: 0 | E10: Q4 | F10: Gasto | G10: Real | H10: =16.6+9.9+8.5+56 -> 91 | Y10: =SUM(Gasto_real[[#This Row],[Transporte]:[U2B Premium]]) -> 91
A11: 46152 | B11: 46143 | C11: 46157 | D11: 0 | E11: Q4 | F11: Gasto | G11: Real | O11: 1800 | Y11: =SUM(Gasto_real[[#This Row],[Transporte]:[U2B Premium]]) -> 1800
A12: 46153 | B12: 46143 | C12: 46157 | D12: 0 | E12: Q4 | F12: Gasto | G12: Real | H12: =16.6+9.9+8.5+67 -> 102 | Y12: =SUM(Gasto_real[[#This Row],[Transporte]:[U2B Premium]]) -> 102
A13: 46154 | B13: 46143 | C13: 46157 | D13: 0 | E13: Q4 | F13: Gasto | G13: Real | H13: =16.6+15+9.9+8.35 -> 49.85 | Y13: =SUM(Gasto_real[[#This Row],[Transporte]:[U2B Premium]]) -> 49.85
A14: 46155 | B14: 46143 | C14: 46157 | D14: 0 | E14: Q4 | F14: Gasto | G14: Real | H14: =16.6+9.9+8.5+58 -> 93 | Y14: =SUM(Gasto_real[[#This Row],[Transporte]:[U2B Premium]]) -> 93
A15: 46156 | B15: 46143 | C15: 46157 | D15: 0 | E15: Q4 | F15: Gasto | G15: Real | H15: =16.7+7.5+9.9+8.35 -> 42.45 | Y15: =SUM(Gasto_real[[#This Row],[Transporte]:[U2B Premium]]) -> 42.45
A16: 46157 | B16: 46143 | C16: 46157 | D16: 0 | E16: Q4 | F16: Gasto | G16: Real | H16: =16.7+7.5+9.9+8.35 -> 42.45 | Y16: =SUM(Gasto_real[[#This Row],[Transporte]:[U2B Premium]]) -> 42.45
A17: 46158 | B17: 46158 | C17: 46173 | D17: 1 | E17: Q5 | F17: Gasto | G17: Real | H17: =16.7+7.5+9.9+8.35 -> 42.45 | I17: 446 | J17: 899 | K17: 239 | L17: 139 | O17: 1800 | P17: 2000 | Q17: 70 | T17: 321 | Y17: =SUM(Gasto_real[[#This Row],[Transporte]:[U2B Premium]]) -> 5956.45
A18: 46159 | B18: 46158 | C18: 46173 | D18: 0 | E18: Q5 | F18: Gasto | G18: Real | P18: 215.1 | Y18: =SUM(Gasto_real[[#This Row],[Transporte]:[U2B Premium]]) -> 215.1
A19: 46160 | B19: 46158 | C19: 46173 | D19: 0 | E19: Q5 | F19: Gasto | G19: Real | H19: =16.7+7.5+9.9+8.35 -> 42.45 | Y19: =SUM(Gasto_real[[#This Row],[Transporte]:[U2B Premium]]) -> 42.45
A20: 46161 | B20: 46158 | C20: 46173 | D20: 0 | E20: Q5 | F20: Gasto | G20: Real | H20: =16.7+7.5+9.9+8.35 -> 42.45 | Y20: =SUM(Gasto_real[[#This Row],[Transporte]:[U2B Premium]]) -> 42.45
A21: 46162 | B21: 46158 | C21: 46173 | D21: 0 | E21: Q5 | F21: Gasto | G21: Real | H21: =16.7+7.5+9.9+8.35 -> 42.45 | Y21: =SUM(Gasto_real[[#This Row],[Transporte]:[U2B Premium]]) -> 42.45
A22: 46163 | B22: 46158 | C22: 46173 | D22: 0 | E22: Q5 | F22: Gasto | G22: Real | H22: =16.7+7.5+9.9+8.35 -> 42.45 | Y22: =SUM(Gasto_real[[#This Row],[Transporte]:[U2B Premium]]) -> 42.45
A23: 46164 | B23: 46158 | C23: 46173 | D23: 0 | E23: Q5 | F23: Gasto | G23: Real | H23: =16.7+7.5+9.9+8.35 -> 42.45 | Y23: =SUM(Gasto_real[[#This Row],[Transporte]:[U2B Premium]]) -> 42.45
A24: 46165 | B24: 46158 | C24: 46173 | D24: 2 | E24: Q5 | F24: Gasto | G24: Real | H24: =16.7+7.5+9.9+8.35 -> 42.45 | O24: 1800 | Y24: =SUM(Gasto_real[[#This Row],[Transporte]:[U2B Premium]]) -> 1842.45
A25: 46166 | B25: 46158 | C25: 46173 | D25: 0 | E25: Q5 | F25: Gasto | G25: Real | P25: 450 | Y25: =SUM(Gasto_real[[#This Row],[Transporte]:[U2B Premium]]) -> 450
A26: 46167 | B26: 46158 | C26: 46173 | D26: 0 | E26: Q5 | F26: Gasto | G26: Real | H26: =16.7+7.5+9.9+8.35 -> 42.45 | P26: 1400 | Y26: =SUM(Gasto_real[[#This Row],[Transporte]:[U2B Premium]]) -> 1442.45
A27: 46168 | B27: 46158 | C27: 46173 | D27: 0 | E27: Q5 | F27: Gasto | G27: Real | H27: =16.7+7.5+9.9+8.35 -> 42.45 | Y27: =SUM(Gasto_real[[#This Row],[Transporte]:[U2B Premium]]) -> 42.45
A28: 46169 | B28: 46158 | C28: 46173 | D28: 0 | E28: Q5 | F28: Gasto | G28: Real | H28: =16.7+7.5+9.9+8.35 -> 42.45 | Y28: =SUM(Gasto_real[[#This Row],[Transporte]:[U2B Premium]]) -> 42.45
A29: 46170 | B29: 46158 | C29: 46173 | D29: 0 | E29: Q5 | F29: Gasto | G29: Real | H29: =16.7+7.5+9.9+8.35 -> 42.45 | Y29: =SUM(Gasto_real[[#This Row],[Transporte]:[U2B Premium]]) -> 42.45
A30: 46171 | B30: 46158 | C30: 46173 | D30: 0 | E30: Q5 | F30: Gasto | G30: Real | H30: =16.7+7.5+9.9+8.35 -> 42.45 | Y30: =SUM(Gasto_real[[#This Row],[Transporte]:[U2B Premium]]) -> 42.45
A31: 46172 | B31: 46158 | C31: 46173 | D31: 0 | E31: Q5 | F31: Gasto | G31: Real | H31: =16.7+7.5+9.9+8.35 -> 42.45 | Y31: =SUM(Gasto_real[[#This Row],[Transporte]:[U2B Premium]]) -> 42.45
A32: 46173 | B32: 46158 | C32: 46173 | D32: 0 | E32: Q5 | F32: Gasto | G32: Real | Y32: =SUM(Gasto_real[[#This Row],[Transporte]:[U2B Premium]]) -> 0
A33: 46174 | B33: 46174 | C33: 46188 | D33: 1 | E33: Q6 | F33: Gasto | G33: Real | H33: =16.7+7.5+9.9+8.35 -> 42.45 | M33: 600 | O33: 1800 | R33: 70 | S33: 70 | Y33: =SUM(Gasto_real[[#This Row],[Transporte]:[U2B Premium]]) -> 2582.45
A34: 46175 | B34: 46174 | C34: 46188 | D34: 0 | E34: Q6 | F34: Gasto | G34: Real | H34: =16.7+7.5+9.9+8.35 -> 42.45 | Y34: =SUM(Gasto_real[[#This Row],[Transporte]:[U2B Premium]]) -> 42.45
A35: 46176 | B35: 46174 | C35: 46188 | D35: 0 | E35: Q6 | F35: Gasto | G35: Real | H35: =16.7+7.5+9.9+8.35 -> 42.45 | Y35: =SUM(Gasto_real[[#This Row],[Transporte]:[U2B Premium]]) -> 42.45
A36: 46177 | B36: 46174 | C36: 46188 | D36: 0 | E36: Q6 | F36: Gasto | G36: Real | H36: =16.7+7.5+9.9+8.35 -> 42.45 | Y36: =SUM(Gasto_real[[#This Row],[Transporte]:[U2B Premium]]) -> 42.45
A37: 46178 | B37: 46174 | C37: 46188 | D37: 0 | E37: Q6 | F37: Gasto | G37: Real | H37: =16.7+7.5+9.9+8.35 -> 42.45 | Y37: =SUM(Gasto_real[[#This Row],[Transporte]:[U2B Premium]]) -> 42.45
A38: 46179 | B38: 46174 | C38: 46188 | D38: 0 | E38: Q6 | F38: Gasto | G38: Real | H38: =16.7+7.5+9.9+8.35 -> 42.45 | Y38: =SUM(Gasto_real[[#This Row],[Transporte]:[U2B Premium]]) -> 42.45
A39: 46180 | B39: 46174 | C39: 46188 | D39: 0 | E39: Q6 | F39: Gasto | G39: Real | Y39: =SUM(Gasto_real[[#This Row],[Transporte]:[U2B Premium]]) -> 0
A40: 46181 | B40: 46174 | C40: 46188 | D40: 2 | E40: Q6 | F40: Gasto | G40: Real | H40: =16.7+7.5+9.9+8.35 -> 42.45 | O40: 1800 | Y40: =SUM(Gasto_real[[#This Row],[Transporte]:[U2B Premium]]) -> 1842.45
...

Sheet Evento R
A1: Fecha | B1: Inicio | C1: Fin | D1: DíaP | E1: NQ | F1: Tipo | G1: Estatus | H1: 10deMay | I1: Aniversario | J1: Cumple Lucian | K1: Hotel | L1: Vuelos | M1: Navidad | N1: Baupad | O1: Comedor | P1: Sala | Q1: Clima
A2: 46143 | B2: 46143 | C2: 46157 | D2: 1 | E2: Q4 | F2: Evento | G2: Real | H2: 2400 | N2: 940 | Q2: 5400 | AC2: =SUM(Evento_Real[[#This Row],[10deMay]:[Clima]]) -> 8740
A3: 46144 | B3: 46143 | C3: 46157 | D3: 0 | E3: Q4 | F3: Evento | G3: Real | AC3: =SUM(Evento_Real[[#This Row],[10deMay]:[Clima]]) -> 0
A4: 46145 | B4: 46143 | C4: 46157 | D4: 0 | E4: Q4 | F4: Evento | G4: Real | AC4: =SUM(Evento_Real[[#This Row],[10deMay]:[Clima]]) -> 0
A5: 46146 | B5: 46143 | C5: 46157 | D5: 0 | E5: Q4 | F5: Evento | G5: Real | AC5: =SUM(Evento_Real[[#This Row],[10deMay]:[Clima]]) -> 0
A6: 46147 | B6: 46143 | C6: 46157 | D6: 0 | E6: Q4 | F6: Evento | G6: Real | AC6: =SUM(Evento_Real[[#This Row],[10deMay]:[Clima]]) -> 0
A7: 46148 | B7: 46143 | C7: 46157 | D7: 0 | E7: Q4 | F7: Evento | G7: Real | AC7: =SUM(Evento_Real[[#This Row],[10deMay]:[Clima]]) -> 0
A8: 46149 | B8: 46143 | C8: 46157 | D8: 0 | E8: Q4 | F8: Evento | G8: Real | AC8: =SUM(Evento_Real[[#This Row],[10deMay]:[Clima]]) -> 0
A9: 46150 | B9: 46143 | C9: 46157 | D9: 0 | E9: Q4 | F9: Evento | G9: Real | AC9: =SUM(Evento_Real[[#This Row],[10deMay]:[Clima]]) -> 0
A10: 46151 | B10: 46143 | C10: 46157 | D10: 0 | E10: Q4 | F10: Evento | G10: Real | AC10: =SUM(Evento_Real[[#This Row],[10deMay]:[Clima]]) -> 0
A11: 46152 | B11: 46143 | C11: 46157 | D11: 0 | E11: Q4 | F11: Evento | G11: Real | AC11: =SUM(Evento_Real[[#This Row],[10deMay]:[Clima]]) -> 0
A12: 46153 | B12: 46143 | C12: 46157 | D12: 0 | E12: Q4 | F12: Evento | G12: Real | AC12: =SUM(Evento_Real[[#This Row],[10deMay]:[Clima]]) -> 0
A13: 46154 | B13: 46143 | C13: 46157 | D13: 0 | E13: Q4 | F13: Evento | G13: Real | AC13: =SUM(Evento_Real[[#This Row],[10deMay]:[Clima]]) -> 0
A14: 46155 | B14: 46143 | C14: 46157 | D14: 0 | E14: Q4 | F14: Evento | G14: Real | AC14: =SUM(Evento_Real[[#This Row],[10deMay]:[Clima]]) -> 0
... A16: 46157 | B16: 46143 | C16: 46157 | D16: 0 | E16: Q4 | F16: Evento | G16: Real | AC16: =SUM(Evento_Real[[#This Row],[10deMay]:[Clima]]) -> 0
A17: 46158 | B17: 46158 | C17: 46173 | D17: 1 | E17: Q5 | F17: Evento | G17: Real | L17: 8000 | N17: 4250 | AC17: =SUM(Evento_Real[[#This Row],[10deMay]:[Clima]]) -> 12250
A18: 46159 | B18: 46158 | C18: 46173 | D18: 0 | E18: Q5 | F18: Evento | G18: Real | AC18: =SUM(Evento_Real[[#This Row],[10deMay]:[Clima]]) -> 0
A19: 46160 | B19: 46158 | C19: 46173 | D19: 0 | E19: Q5 | F19: Evento | G19: Real | AC19: =SUM(Evento_Real[[#This Row],[10deMay]:[Clima]]) -> 0
A20: 46161 | B20: 46158 | C20: 46173 | D20: 0 | E20: Q5 | F20: Evento | G20: Real | AC20: =SUM(Evento_Real[[#This Row],[10deMay]:[Clima]]) -> 0
A21: 46162 | B21: 46158 | C21: 46173 | D21: 0 | E21: Q5 | F21: Evento | G21: Real | AC21: =SUM(Evento_Real[[#This Row],[10deMay]:[Clima]]) -> 0
A22: 46163 | B22: 46158 | C22: 46173 | D22: 0 | E22: Q5 | F22: Evento | G22: Real | AC22: =SUM(Evento_Real[[#This Row],[10deMay]:[Clima]]) -> 0
A23: 46164 | B23: 46158 | C23: 46173 | D23: 0 | E23: Q5 | F23: Evento | G23: Real | AC23: =SUM(Evento_Real[[#This Row],[10deMay]:[Clima]]) -> 0
A24: 46165 | B24: 46158 | C24: 46173 | D24: 0 | E24: Q5 | F24: Evento | G24: Real | AC24: =SUM(Evento_Real[[#This Row],[10deMay]:[Clima]]) -> 0
A25: 46166 | B25: 46158 | C25: 46173 | D25: 0 | E25: Q5 | F25: Evento | G25: Real | AC25: =SUM(Evento_Real[[#This Row],[10deMay]:[Clima]]) -> 0
A26: 46167 | B26: 46158 | C26: 46173 | D26: 0 | E26: Q5 | F26: Evento | G26: Real | AC26: =SUM(Evento_Real[[#This Row],[10deMay]:[Clima]]) -> 0
A27: 46168 | B27: 46158 | C27: 46173 | D27: 0 | E27: Q5 | F27: Evento | G27: Real | AC27: =SUM(Evento_Real[[#This Row],[10deMay]:[Clima]]) -> 0
A28: 46169 | B28: 46158 | C28: 46173 | D28: 0 | E28: Q5 | F28: Evento | G28: Real | AC28: =SUM(Evento_Real[[#This Row],[10deMay]:[Clima]]) -> 0
A29: 46170 | B29: 46158 | C29: 46173 | D29: 0 | E29: Q5 | F29: Evento | G29: Real | AC29: =SUM(Evento_Real[[#This Row],[10deMay]:[Clima]]) -> 0
... A32: 46173 | B32: 46158 | C32: 46173 | D32: 0 | E32: Q5 | F32: Evento | G32: Real | AC32: =SUM(Evento_Real[[#This Row],[10deMay]:[Clima]]) -> 0
A33: 46174 | B33: 46174 | C33: 46188 | D33: 1 | E33: Q6 | F33: Evento | G33: Real | K33: 3000 | N33: 3750 | Q33: 2800 | AC33: =SUM(Evento_Real[[#This Row],[10deMay]:[Clima]]) -> 9550
A34: 46175 | B34: 46174 | C34: 46188 | D34: 0 | E34: Q6 | F34: Evento | G34: Real | AC34: =SUM(Evento_Real[[#This Row],[10deMay]:[Clima]]) -> 0
A35: 46176 | B35: 46174 | C35: 46188 | D35: 0 | E35: Q6 | F35: Evento | G35: Real | AC35: =SUM(Evento_Real[[#This Row],[10deMay]:[Clima]]) -> 0
A36: 46177 | B36: 46174 | C36: 46188 | D36: 0 | E36: Q6 | F36: Evento | G36: Real | AC36: =SUM(Evento_Real[[#This Row],[10deMay]:[Clima]]) -> 0
A37: 46178 | B37: 46174 | C37: 46188 | D37: 0 | E37: Q6 | F37: Evento | G37: Real | AC37: =SUM(Evento_Real[[#This Row],[10deMay]:[Clima]]) -> 0
A38: 46179 | B38: 46174 | C38: 46188 | D38: 0 | E38: Q6 | F38: Evento | G38: Real | AC38: =SUM(Evento_Real[[#This Row],[10deMay]:[Clima]]) -> 0
A39: 46180 | B39: 46174 | C39: 46188 | D39: 0 | E39: Q6 | F39: Evento | G39: Real | AC39: =SUM(Evento_Real[[#This Row],[10deMay]:[Clima]]) -> 0
A40: 46181 | B40: 46174 | C40: 46188 | D40: 0 | E40: Q6 | F40: Evento | G40: Real | AC40: =SUM(Evento_Real[[#This Row],[10deMay]:[Clima]]) -> 0
A41: 46182 | B41: 46174 | C41: 46188 | D41: 0 | E41: Q6 | F41: Evento | G41: Real | AC41: =SUM(Evento_Real[[#This Row],[10deMay]:[Clima]]) -> 0
A42: 46183 | B42: 46174 | C42: 46188 | D42: 0 | E42: Q6 | F42: Evento | G42: Real | AC42: =SUM(Evento_Real[[#This Row],[10deMay]:[Clima]]) -> 0
A43: 46184 | B43: 46174 | C43: 46188 | D43: 0 | E43: Q6 | F43: Evento | G43: Real | AC43: =SUM(Evento_Real[[#This Row],[10deMay]:[Clima]]) -> 0
...

Sheet Goals
A1: Goal | B1: 10deMay | C1: Aniversario | D1: Cumple Lucian | E1: Hotel | F1: Vuelos | G1: Navidad | H1: Baupad | I1: Comedor | J1: Sala
A2: Proyectado | B2: 1400 | C2: 5300 | D2: 1500 | E2: 25000 | F2: 14700 | G2: 25000 | H2: 5500 | I2: 0 | J2: 20000
A3: Real | B3: =SUM('Evento R'!H:H) -> 2400 | C3: =SUM('Evento R'!I:I) -> 2500 | D3: =SUM('Evento R'!J:J) -> 0 | E3: =SUM('Evento R'!K:K) -> 30000 | F3: =SUM('Evento R'!L:L) -> 12200 | G3: =SUM('Evento R'!M:M) -> 15000 | H3: =SUM('Evento R'!N:N) -> 12690 | I3: =SUM('Evento R'!O:O) -> 0 | J3: =SUM('Evento R'!P:P) -> 20000

Sheet Resumen
A1: Fecha | B1: Inicio | C1: Fin | D1: DíaP | E1: NQ | F1: S | G1: N | H1: TR | I1: AG | J1: IZ | K1: Mov | L1: Nx | M1: Ny | N1: LZ | O1: Dsp | P1: og | Q1: U1 | R1: D+ | S1: Pr | T1: u2 | U1: G | V1: 10m | W1: A1 | X1: Lu | Y1: Ht | Z1: Vu | AA1: Nv | AB1: Bp | AC1: Co | AD1: Sla | AE1: Cli | AF1: Ev | AG1: B | AH1: AN
A2: 46158 | B2: 46158 | C2: 46173 | D2: 1 | E2: Q5 | G2: =SUMIFS(Ingresos!H:H,Ingresos!A:A,Resumen!A2)+SUMIFS(Ingresos!I:I,Ingresos!A:A,Resumen!A2)+SUMIFS(Ingresos!K:K,Ingresos!A:A,Resumen!A2)+F2 -> 21000 | H2: =SUMIFS('Gasto Real'!H:H,'Gasto Real'!$E:$E,Resumen!$E2) -> 551.85 | I2: =SUMIFS('Gasto Real'!I:I,'Gasto Real'!$E:$E,Resumen!$E2) -> 446 | J2: =SUMIFS('Gasto Real'!J:J,'Gasto Real'!$E:$E,Resumen!$E2) -> 899 | K2: =SUMIFS('Gasto Real'!K:K,'Gasto Real'!$E:$E,Resumen!$E2) -> 239 | L2: =SUMIFS('Gasto Real'!L:L,'Gasto Real'!$E:$E,Resumen!$E2) -> 139 | M2: =SUMIFS('Gasto Real'!M:M,'Gasto Real'!$E:$E,Resumen!$E2) -> 0 | N2: =SUMIFS('Gasto Real'!N:N,'Gasto Real'!$E:$E,Resumen!$E2) -> 0 | O2: =SUMIFS('Gasto Real'!O:O,'Gasto Real'!$E:$E,Resumen!$E2) -> 3600 | P2: =SUMIFS('Gasto Real'!P:P,'Gasto Real'!$E:$E,Resumen!$E2) -> 4065.1 | Q2: =SUMIFS('Gasto Real'!Q:Q,'Gasto Real'!$E:$E,Resumen!$E2) -> 70 | R2: =SUMIFS('Gasto Real'!R:R,'Gasto Real'!$E:$E,Resumen!$E2) -> 0 | S2: =SUMIFS('Gasto Real'!S:S,'Gasto Real'!$E:$E,Resumen!$E2) -> 0 | T2: =SUMIFS('Gasto Real'!T:T,'Gasto Real'!$E:$E,Resumen!$E2) -> 321 | U2: =SUM(H2:T2)*-1 -> -10330.95 | V2: =SUMIFS('Evento R'!H:H,'Evento R'!$E:$E,Resumen!$E2) -> 0 | W2: =SUMIFS('Evento R'!I:I,'Evento R'!$E:$E,Resumen!$E2) -> 0 | X2: =SUMIFS('Evento R'!J:J,'Evento R'!$E:$E,Resumen!$E2) -> 0 | Y2: =SUMIFS('Evento R'!K:K,'Evento R'!$E:$E,Resumen!$E2) -> 0 | Z2: =SUMIFS('Evento R'!L:L,'Evento R'!$E:$E,Resumen!$E2) -> 8000 | AA2: =SUMIFS('Evento R'!M:M,'Evento R'!$E:$E,Resumen!$E2) -> 0 | AB2: =SUMIFS('Evento R'!N:N,'Evento R'!$E:$E,Resumen!$E2) -> 4250 | AC2: =SUMIFS('Evento R'!O:O,'Evento R'!$E:$E,Resumen!$E2) -> 0 | AD2: =SUMIFS('Evento R'!P:P,'Evento R'!$E:$E,Resumen!$E2) -> 0 | AE2: =SUMIFS('Evento R'!Q:Q,'Evento R'!$E:$E,Resumen!$E2) -> 0 | AF2: =SUM(V2:AE2)*-1 -> -12250 | AH2: =SUM(G2)+SUM(U2,AF2) -> -1580.95
A3: 46174 | B3: 46174 | C3: 46188 | D3: 1 | E3: Q6 | F3: =G3+AH2 -> 13419.05 | G3: =SUMIFS(Ingresos!H:H,Ingresos!A:A,Resumen!A3)+SUMIFS(Ingresos!I:I,Ingresos!A:A,Resumen!A3)+SUMIFS(Ingresos!K:K,Ingresos!A:A,Resumen!A3) -> 15000 | H3: =SUMIFS('Gasto Real'!H:H,'Gasto Real'!$E:$E,Resumen!$E3) -> 551.85 | I3: =SUMIFS('Gasto Real'!I:I,'Gasto Real'!$E:$E,Resumen!$E3) -> 0 | J3: =SUMIFS('Gasto Real'!J:J,'Gasto Real'!$E:$E,Resumen!$E3) -> 0 | K3: =SUMIFS('Gasto Real'!K:K,'Gasto Real'!$E:$E,Resumen!$E3) -> 0 | L3: =SUMIFS('Gasto Real'!L:L,'Gasto Real'!$E:$E,Resumen!$E3) -> 0 | M3: =SUMIFS('Gasto Real'!M:M,'Gasto Real'!$E:$E,Resumen!$E3) -> 600 | N3: =SUMIFS('Gasto Real'!N:N,'Gasto Real'!$E:$E,Resumen!$E3) -> 0 | O3: =SUMIFS('Gasto Real'!O:O,'Gasto Real'!$E:$E,Resumen!$E3) -> 3600 | P3: =SUMIFS('Gasto Real'!P:P,'Gasto Real'!$E:$E,Resumen!$E3) -> 0 | Q3: =SUMIFS('Gasto Real'!Q:Q,'Gasto Real'!$E:$E,Resumen!$E3) -> 0 | R3: =SUMIFS('Gasto Real'!R:R,'Gasto Real'!$E:$E,Resumen!$E3) -> 70 | S3: =SUMIFS('Gasto Real'!S:S,'Gasto Real'!$E:$E,Resumen!$E3) -> 70 | T3: =SUMIFS('Gasto Real'!T:T,'Gasto Real'!$E:$E,Resumen!$E3) -> 0 | U3: =SUM(H3:T3)*-1 -> -4891.85 | V3: =SUMIFS('Evento R'!H:H,'Evento R'!$E:$E,Resumen!$E3) -> 0 | W3: =SUMIFS('Evento R'!I:I,'Evento R'!$E:$E,Resumen!$E3) -> 0 | X3: =SUMIFS('Evento R'!J:J,'Evento R'!$E:$E,Resumen!$E3) -> 0 | Y3: =SUMIFS('Evento R'!K:K,'Evento R'!$E:$E,Resumen!$E3) -> 3000 | Z3: =SUMIFS('Evento R'!L:L,'Evento R'!$E:$E,Resumen!$E3) -> 0 | AA3: =SUMIFS('Evento R'!M:M,'Evento R'!$E:$E,Resumen!$E3) -> 0 | AB3: =SUMIFS('Evento R'!N:N,'Evento R'!$E:$E,Resumen!$E3) -> 3750 | AC3: =SUMIFS('Evento R'!O:O,'Evento R'!$E:$E,Resumen!$E3) -> 0 | AD3: =SUMIFS('Evento R'!P:P,'Evento R'!$E:$E,Resumen!$E3) -> 0 | AE3: =SUMIFS('Evento R'!Q:Q,'Evento R'!$E:$E,Resumen!$E3) -> 2800 | AF3: =SUM(V3:AE3)*-1 -> -9550 | AH3: =SUM(F3)+SUM(U3,AF3) -> -1022.8
A4: 46189 | B4: 46189 | C4: 46203 | D4: 1 | E4: Q7 | F4: =G4+AH3 -> 13977.2 | G4: =SUMIFS(Ingresos!H:H,Ingresos!A:A,Resumen!A4)+SUMIFS(Ingresos!I:I,Ingresos!A:A,Resumen!A4)+SUMIFS(Ingresos!K:K,Ingresos!A:A,Resumen!A4) -> 15000 | H4: =SUMIFS('Gasto Real'!H:H,'Gasto Real'!$E:$E,Resumen!$E4) -> 551.85 | I4: =SUMIFS('Gasto Real'!I:I,'Gasto Real'!$E:$E,Resumen!$E4) -> 450 | J4: =SUMIFS('Gasto Real'!J:J,'Gasto Real'!$E:$E,Resumen!$E4) -> 0 | K4: =SUMIFS('Gasto Real'!K:K,'Gasto Real'!$E:$E,Resumen!$E4) -> 239 | L4: =SUMIFS('Gasto Real'!L:L,'Gasto Real'!$E:$E,Resumen!$E4) -> 139 | M4: =SUMIFS('Gasto Real'!M:M,'Gasto Real'!$E:$E,Resumen!$E4) -> 0 | N4: =SUMIFS('Gasto Real'!N:N,'Gasto Real'!$E:$E,Resumen!$E4) -> 0 | O4: =SUMIFS('Gasto Real'!O:O,'Gasto Real'!$E:$E,Resumen!$E4) -> 3600 | P4: =SUMIFS('Gasto Real'!P:P,'Gasto Real'!$E:$E,Resumen!$E4) -> 0 | Q4: =SUMIFS('Gasto Real'!Q:Q,'Gasto Real'!$E:$E,Resumen!$E4) -> 70 | R4: =SUMIFS('Gasto Real'!R:R,'Gasto Real'!$E:$E,Resumen!$E4) -> 0 | S4: =SUMIFS('Gasto Real'!S:S,'Gasto Real'!$E:$E,Resumen!$E4) -> 0 | T4: =SUMIFS('Gasto Real'!T:T,'Gasto Real'!$E:$E,Resumen!$E4) -> 321 | U4: =SUM(H4:T4)*-1 -> -5370.85 | V4: =SUMIFS('Evento R'!H:H,'Evento R'!$E:$E,Resumen!$E4) -> 0 | W4: =SUMIFS('Evento R'!I:I,'Evento R'!$E:$E,Resumen!$E4) -> 0 | X4: =SUMIFS('Evento R'!J:J,'Evento R'!$E:$E,Resumen!$E4) -> 0 | Y4: =SUMIFS('Evento R'!K:K,'Evento R'!$E:$E,Resumen!$E4) -> 5000 | Z4: =SUMIFS('Evento R'!L:L,'Evento R'!$E:$E,Resumen!$E4) -> 0 | AA4: =SUMIFS('Evento R'!M:M,'Evento R'!$E:$E,Resumen!$E4) -> 0 | AB4: =SUMIFS('Evento R'!N:N,'Evento R'!$E:$E,Resumen!$E4) -> 3750 | AC4: =SUMIFS('Evento R'!O:O,'Evento R'!$E:$E,Resumen!$E4) -> 0 | AD4: =SUMIFS('Evento R'!P:P,'Evento R'!$E:$E,Resumen!$E4) -> 0 | AE4: =SUMIFS('Evento R'!Q:Q,'Evento R'!$E:$E,Resumen!$E4) -> 0 | AF4: =SUM(V4:AE4)*-1 -> -8750 | AH4: =SUM(F4)+SUM(U4,AF4) -> -143.65 | AO4: actual | AP4: 320 | AQ4: nuevo | AR4: =SUM(AP4:AP10) -> 2790 | AS4: Cbp | AT4: =SUM(AR4:AR6) -> 990 | AU4: Semi | AV4: =SUM(AT4:AT10) -> -1000 | AW4: Final | AX4: =SUM(AV4:AV6) -> -1000
A5: 46204 | B5: 46204 | C5: 46218 | D5: 1 | E5: Q8 | F5: =G5+AH4 -> 14856.35 | G5: =SUMIFS(Ingresos!H:H,Ingresos!A:A,Resumen!A5)+SUMIFS(Ingresos!I:I,Ingresos!A:A,Resumen!A5)+SUMIFS(Ingresos!K:K,Ingresos!A:A,Resumen!A5) -> 15000 | H5: =SUMIFS('Gasto Real'!H:H,'Gasto Real'!$E:$E,Resumen!$E5) -> 551.85 | I5: =SUMIFS('Gasto Real'!I:I,'Gasto Real'!$E:$E,Resumen!$E5) -> 0 | J5: =SUMIFS('Gasto Real'!J:J,'Gasto Real'!$E:$E,Resumen!$E5) -> 0 | K5: =SUMIFS('Gasto Real'!K:K,'Gasto Real'!$E:$E,Resumen!$E5) -> 0 | L5: =SUMIFS('Gasto Real'!L:L,'Gasto Real'!$E:$E,Resumen!$E5) -> 0 | M5: =SUMIFS('Gasto Real'!M:M,'Gasto Real'!$E:$E,Resumen!$E5) -> 0 | N5: =SUMIFS('Gasto Real'!N:N,'Gasto Real'!$E:$E,Resumen!$E5) -> 600 | O5: =SUMIFS('Gasto Real'!O:O,'Gasto Real'!$E:$E,Resumen!$E5) -> 3600 | P5: =SUMIFS('Gasto Real'!P:P,'Gasto Real'!$E:$E,Resumen!$E5) -> 0 | Q5: =SUMIFS('Gasto Real'!Q:Q,'Gasto Real'!$E:$E,Resumen!$E5) -> 0 | R5: =SUMIFS('Gasto Real'!R:R,'Gasto Real'!$E:$E,Resumen!$E5) -> 140 | S5: =SUMIFS('Gasto Real'!S:S,'Gasto Real'!$E:$E,Resumen!$E5) -> 140 | T5: =SUMIFS('Gasto Real'!T:T,'Gasto Real'!$E:$E,Resumen!$E5) -> 0 | U5: =SUM(H5:T5)*-1 -> -5031.85 | V5: =SUMIFS('Evento R'!H:H,'Evento R'!$E:$E,Resumen!$E5) -> 0 | W5: =SUMIFS('Evento R'!I:I,'Evento R'!$E:$E,Resumen!$E5) -> 0 | X5: =SUMIFS('Evento R'!J:J,'Evento R'!$E:$E,Resumen!$E5) -> 0 | Y5: =SUMIFS('Evento R'!K:K,'Evento R'!$E:$E,Resumen!$E5) -> 5000 | Z5: =SUMIFS('Evento R'!L:L,'Evento R'!$E:$E,Resumen!$E5) -> 0 | AA5: =SUMIFS('Evento R'!M:M,'Evento R'!$E:$E,Resumen!$E5) -> 0 | AB5: =SUMIFS('Evento R'!N:N,'Evento R'!$E:$E,Resumen!$E5) -> 0 | AC5: =SUMIFS('Evento R'!O:O,'Evento R'!$E:$E,Resumen!$E5) -> 0 | AD5: =SUMIFS('Evento R'!P:P,'Evento R'!$E:$E,Resumen!$E5) -> 0 | AE5: =SUMIFS('Evento R'!Q:Q,'Evento R'!$E:$E,Resumen!$E5) -> 0 | AF5: =SUM(V5:AE5)*-1 -> -5000 | AH5: =SUM(F5)+SUM(U5,AF5) -> 4824.5 | AO5: PTU | AP5: 470 | AQ5: Cinsta | AR5: -1800 | AS5: dsp2 | AT5: -1800
A6: 46219 | B6: 46219 | C6: 46234 | D6: 1 | E6: Q9 | F6: =G6+AH5 -> 19824.5 | G6: =SUMIFS(Ingresos!H:H,Ingresos!A:A,Resumen!A6)+SUMIFS(Ingresos!I:I,Ingresos!A:A,Resumen!A6)+SUMIFS(Ingresos!K:K,Ingresos!A:A,Resumen!A6) -> 15000 | H6: =SUMIFS('Gasto Real'!H:H,'Gasto Real'!$E:$E,Resumen!$E6) -> 594.3 | I6: =SUMIFS('Gasto Real'!I:I,'Gasto Real'!$E:$E,Resumen!$E6) -> 450 | J6: =SUMIFS('Gasto Real'!J:J,'Gasto Real'!$E:$E,Resumen!$E6) -> 449 | K6: =SUMIFS('Gasto Real'!K:K,'Gasto Real'!$E:$E,Resumen!$E6) -> 239 | L6: =SUMIFS('Gasto Real'!L:L,'Gasto Real'!$E:$E,Resumen!$E6) -> 139 | M6: =SUMIFS('Gasto Real'!M:M,'Gasto Real'!$E:$E,Resumen!$E6) -> 0 | N6: =SUMIFS('Gasto Real'!N:N,'Gasto Real'!$E:$E,Resumen!$E6) -> 0 | O6: =SUMIFS('Gasto Real'!O:O,'Gasto Real'!$E:$E,Resumen!$E6) -> 3600 | P6: =SUMIFS('Gasto Real'!P:P,'Gasto Real'!$E:$E,Resumen!$E6) -> 0 | Q6: =SUMIFS('Gasto Real'!Q:Q,'Gasto Real'!$E:$E,Resumen!$E6) -> 70 | R6: =SUMIFS('Gasto Real'!R:R,'Gasto Real'!$E:$E,Resumen!$E6) -> 0 | S6: =SUMIFS('Gasto Real'!S:S,'Gasto Real'!$E:$E,Resumen!$E6) -> 0 | T6: =SUMIFS('Gasto Real'!T:T,'Gasto Real'!$E:$E,Resumen!$E6) -> 321 | U6: =SUM(H6:T6)*-1 -> -5862.3 | V6: =SUMIFS('Evento R'!H:H,'Evento R'!$E:$E,Resumen!$E6) -> 0 | W6: =SUMIFS('Evento R'!I:I,'Evento R'!$E:$E,Resumen!$E6) -> 0 | X6: =SUMIFS('Evento R'!J:J,'Evento R'!$E:$E,Resumen!$E6) -> 0 | Y6: =SUMIFS('Evento R'!K:K,'Evento R'!$E:$E,Resumen!$E6) -> 5000 | Z6: =SUMIFS('Evento R'!L:L,'Evento R'!$E:$E,Resumen!$E6) -> 0 | AA6: =SUMIFS('Evento R'!M:M,'Evento R'!$E:$E,Resumen!$E6) -> 0 | AB6: =SUMIFS('Evento R'!N:N,'Evento R'!$E:$E,Resumen!$E6) -> 0 | AC6: =SUMIFS('Evento R'!O:O,'Evento R'!$E:$E,Resumen!$E6) -> 0 | AD6: =SUMIFS('Evento R'!P:P,'Evento R'!$E:$E,Resumen!$E6) -> 0 | AE6: =SUMIFS('Evento R'!Q:Q,'Evento R'!$E:$E,Resumen!$E6) -> 0 | AF6: =SUM(V6:AE6)*-1 -> -5000 | AH6: =SUM(F6)+SUM(U6,AF6) -> 8962.2 | AO6: clm | AP6: 2000 | AS6: Tra | AT6: -190
A7: 46235 | B7: 46235 | C7: 46249 | D7: 1 | E7: Q10 | F7: =G7+AH6 -> 23962.2 | G7: =SUMIFS(Ingresos!H:H,Ingresos!A:A,Resumen!A7)+SUMIFS(Ingresos!I:I,Ingresos!A:A,Resumen!A7)+SUMIFS(Ingresos!K:K,Ingresos!A:A,Resumen!A7) -> 15000 | H7: =SUMIFS('Gasto Real'!H:H,'Gasto Real'!$E:$E,Resumen!$E7) -> 551.85 | I7: =SUMIFS('Gasto Real'!I:I,'Gasto Real'!$E:$E,Resumen!$E7) -> 0 | J7: =SUMIFS('Gasto Real'!J:J,'Gasto Real'!$E:$E,Resumen!$E7) -> 0 | K7: =SUMIFS('Gasto Real'!K:K,'Gasto Real'!$E:$E,Resumen!$E7) -> 0 | L7: =SUMIFS('Gasto Real'!L:L,'Gasto Real'!$E:$E,Resumen!$E7) -> 0 | M7: =SUMIFS('Gasto Real'!M:M,'Gasto Real'!$E:$E,Resumen!$E7) -> 600 | N7: =SUMIFS('Gasto Real'!N:N,'Gasto Real'!$E:$E,Resumen!$E7) -> 0 | O7: =SUMIFS('Gasto Real'!O:O,'Gasto Real'!$E:$E,Resumen!$E7) -> 3600 | P7: =SUMIFS('Gasto Real'!P:P,'Gasto Real'!$E:$E,Resumen!$E7) -> 0 | Q7: =SUMIFS('Gasto Real'!Q:Q,'Gasto Real'!$E:$E,Resumen!$E7) -> 0 | R7: =SUMIFS('Gasto Real'!R:R,'Gasto Real'!$E:$E,Resumen!$E7) -> 70 | S7: =SUMIFS('Gasto Real'!S:S,'Gasto Real'!$E:$E,Resumen!$E7) -> 70 | T7: =SUMIFS('Gasto Real'!T:T,'Gasto Real'!$E:$E,Resumen!$E7) -> 0 | U7: =SUM(H7:T7)*-1 -> -4891.85 | V7: =SUMIFS('Evento R'!H:H,'Evento R'!$E:$E,Resumen!$E7) -> 0 | W7: =SUMIFS('Evento R'!I:I,'Evento R'!$E:$E,Resumen!$E7) -> 2500 | X7: =SUMIFS('Evento R'!J:J,'Evento R'!$E:$E,Resumen!$E7) -> 0 | Y7: =SUMIFS('Evento R'!K:K,'Evento R'!$E:$E,Resumen!$E7) -> 5000 | Z7: =SUMIFS('Evento R'!L:L,'Evento R'!$E:$E,Resumen!$E7) -> 0 | AA7: =SUMIFS('Evento R'!M:M,'Evento R'!$E:$E,Resumen!$E7) -> 0 | AB7: =SUMIFS('Evento R'!N:N,'Evento R'!$E:$E,Resumen!$E7) -> 0 | AC7: =SUMIFS('Evento R'!O:O,'Evento R'!$E:$E,Resumen!$E7) -> 0 | AD7: =SUMIFS('Evento R'!P:P,'Evento R'!$E:$E,Resumen!$E7) -> 0 | AE7: =SUMIFS('Evento R'!Q:Q,'Evento R'!$E:$E,Resumen!$E7) -> 0 | AF7: =SUM(V7:AE7)*-1 -> -7500 | AH7: =SUM(F7)+SUM(U7,AF7) -> 11570.35
A8: 46250 | B8: 46250 | C8: 46265 | D8: 1 | E8: Q11 | F8: =G8+AH7 -> 26570.35 | G8: =SUMIFS(Ingresos!H:H,Ingresos!A:A,Resumen!A8)+SUMIFS(Ingresos!I:I,Ingresos!A:A,Resumen!A8)+SUMIFS(Ingresos!K:K,Ingresos!A:A,Resumen!A8) -> 15000 | H8: =SUMIFS('Gasto Real'!H:H,'Gasto Real'!$E:$E,Resumen!$E8) -> 551.85 | I8: =SUMIFS('Gasto Real'!I:I,'Gasto Real'!$E:$E,Resumen!$E8) -> 450 | J8: =SUMIFS('Gasto Real'!J:J,'Gasto Real'!$E:$E,Resumen!$E8) -> 449 | K8: =SUMIFS('Gasto Real'!K:K,'Gasto Real'!$E:$E,Resumen!$E8) -> 239 | L8: =SUMIFS('Gasto Real'!L:L,'Gasto Real'!$E:$E,Resumen!$E8) -> 139 | M8: =SUMIFS('Gasto Real'!M:M,'Gasto Real'!$E:$E,Resumen!$E8) -> 0 | N8: =SUMIFS('Gasto Real'!N:N,'Gasto Real'!$E:$E,Resumen!$E8) -> 0 | O8: =SUMIFS('Gasto Real'!O:O,'Gasto Real'!$E:$E,Resumen!$E8) -> 3600 | P8: =SUMIFS('Gasto Real'!P:P,'Gasto Real'!$E:$E,Resumen!$E8) -> 0 | Q8: =SUMIFS('Gasto Real'!Q:Q,'Gasto Real'!$E:$E,Resumen!$E8) -> 70 | R8: =SUMIFS('Gasto Real'!R:R,'Gasto Real'!$E:$E,Resumen!$E8) -> 0 | S8: =SUMIFS('Gasto Real'!S:S,'Gasto Real'!$E:$E,Resumen!$E8) -> 0 | T8: =SUMIFS('Gasto Real'!T:T,'Gasto Real'!$E:$E,Resumen!$E8) -> 321 | U8: =SUM(H8:T8)*-1 -> -5819.85 | V8: =SUMIFS('Evento R'!H:H,'Evento R'!$E:$E,Resumen!$E8) -> 0 | W8: =SUMIFS('Evento R'!I:I,'Evento R'!$E:$E,Resumen!$E8) -> 0 | X8: =SUMIFS('Evento R'!J:J,'Evento R'!$E:$E,Resumen!$E8) -> 0 | Y8: =SUMIFS('Evento R'!K:K,'Evento R'!$E:$E,Resumen!$E8) -> 5000 | Z8: =SUMIFS('Evento R'!L:L,'Evento R'!$E:$E,Resumen!$E8) -> 4200 | AA8: =SUMIFS('Evento R'!M:M,'Evento R'!$E:$E,Resumen!$E8) -> 0 | AB8: =SUMIFS('Evento R'!N:N,'Evento R'!$E:$E,Resumen!$E8) -> 0 | AC8: =SUMIFS('Evento R'!O:O,'Evento R'!$E:$E,Resumen!$E8) -> 0 | AD8: =SUMIFS('Evento R'!P:P,'Evento R'!$E:$E,Resumen!$E8) -> 0 | AE8: =SUMIFS('Evento R'!Q:Q,'Evento R'!$E:$E,Resumen!$E8) -> 0 | AF8: =SUM(V8:AE8)*-1 -> -9200 | AH8: =SUM(F8)+SUM(U8,AF8) -> 11550.5
A9: 46266 | B9: 46266 | C9: 46280 | D9: 1 | E9: Q12 | F9: =G9+AH8 -> 26550.5 | G9: =SUMIFS(Ingresos!H:H,Ingresos!A:A,Resumen!A9)+SUMIFS(Ingresos!I:I,Ingresos!A:A,Resumen!A9)+SUMIFS(Ingresos!K:K,Ingresos!A:A,Resumen!A9) -> 15000 | H9: =SUMIFS('Gasto Real'!H:H,'Gasto Real'!$E:$E,Resumen!$E9) -> 551.85 | I9: =SUMIFS('Gasto Real'!I:I,'Gasto Real'!$E:$E,Resumen!$E9) -> 0 | J9: =SUMIFS('Gasto Real'!J:J,'Gasto Real'!$E:$E,Resumen!$E9) -> 0 | K9: =SUMIFS('Gasto Real'!K:K,'Gasto Real'!$E:$E,Resumen!$E9) -> 0 | L9: =SUMIFS('Gasto Real'!L:L,'Gasto Real'!$E:$E,Resumen!$E9) -> 0 | M9: =SUMIFS('Gasto Real'!M:M,'Gasto Real'!$E:$E,Resumen!$E9) -> 0 | N9: =SUMIFS('Gasto Real'!N:N,'Gasto Real'!$E:$E,Resumen!$E9) -> 1400 | O9: =SUMIFS('Gasto Real'!O:O,'Gasto Real'!$E:$E,Resumen!$E9) -> 3600 | P9: =SUMIFS('Gasto Real'!P:P,'Gasto Real'!$E:$E,Resumen!$E9) -> 0 | Q9: =SUMIFS('Gasto Real'!Q:Q,'Gasto Real'!$E:$E,Resumen!$E9) -> 0 | R9: =SUMIFS('Gasto Real'!R:R,'Gasto Real'!$E:$E,Resumen!$E9) -> 70 | S9: =SUMIFS('Gasto Real'!S:S,'Gasto Real'!$E:$E,Resumen!$E9) -> 70 | T9: =SUMIFS('Gasto Real'!T:T,'Gasto Real'!$E:$E,Resumen!$E9) -> 0 | U9: =SUM(H9:T9)*-1 -> -5691.85 | V9: =SUMIFS('Evento R'!H:H,'Evento R'!$E:$E,Resumen!$E9) -> 0 | W9: =SUMIFS('Evento R'!I:I,'Evento R'!$E:$E,Resumen!$E9) -> 0 | X9: =SUMIFS('Evento R'!J:J,'Evento R'!$E:$E,Resumen!$E9) -> 0 | Y9: =SUMIFS('Evento R'!K:K,'Evento R'!$E:$E,Resumen!$E9) -> 2000 | Z9: =SUMIFS('Evento R'!L:L,'Evento R'!$E:$E,Resumen!$E9) -> 0 | AA9: =SUMIFS('Evento R'!M:M,'Evento R'!$E:$E,Resumen!$E9) -> 0 | AB9: =SUMIFS('Evento R'!N:N,'Evento R'!$E:$E,Resumen!$E9) -> 0 | AC9: =SUMIFS('Evento R'!O:O,'Evento R'!$E:$E,Resumen!$E9) -> 0 | AD9: =SUMIFS('Evento R'!P:P,'Evento R'!$E:$E,Resumen!$E9) -> 10000 | AE9: =SUMIFS('Evento R'!Q:Q,'Evento R'!$E:$E,Resumen!$E9) -> 0 | AF9: =SUM(V9:AE9)*-1 -> -12000 | AH9: =SUM(F9)+SUM(U9,AF9) -> 8858.65
A10: 46281 | B10: 46281 | C10: 46295 | D10: 1 | E10: Q13 | F10: =G10+AH9 -> 23858.65 | G10: =SUMIFS(Ingresos!H:H,Ingresos!A:A,Resumen!A10)+SUMIFS(Ingresos!I:I,Ingresos!A:A,Resumen!A10)+SUMIFS(Ingresos!K:K,Ingresos!A:A,Resumen!A10) -> 15000 | H10: =SUMIFS('Gasto Real'!H:H,'Gasto Real'!$E:$E,Resumen!$E10) -> 551.85 | I10: =SUMIFS('Gasto Real'!I:I,'Gasto Real'!$E:$E,Resumen!$E10) -> 450 | J10: =SUMIFS('Gasto Real'!J:J,'Gasto Real'!$E:$E,Resumen!$E10) -> 449 | K10: =SUMIFS('Gasto Real'!K:K,'Gasto Real'!$E:$E,Resumen!$E10) -> 239 | L10: =SUMIFS('Gasto Real'!L:L,'Gasto Real'!$E:$E,Resumen!$E10) -> 139 | M10: =SUMIFS('Gasto Real'!M:M,'Gasto Real'!$E:$E,Resumen!$E10) -> 0 | N10: =SUMIFS('Gasto Real'!N:N,'Gasto Real'!$E:$E,Resumen!$E10) -> 0 | O10: =SUMIFS('Gasto Real'!O:O,'Gasto Real'!$E:$E,Resumen!$E10) -> 3600 | P10: =SUMIFS('Gasto Real'!P:P,'Gasto Real'!$E:$E,Resumen!$E10) -> 0 | Q10: =SUMIFS('Gasto Real'!Q:Q,'Gasto Real'!$E:$E,Resumen!$E10) -> 70 | R10: =SUMIFS('Gasto Real'!R:R,'Gasto Real'!$E:$E,Resumen!$E10) -> 0 | S10: =SUMIFS('Gasto Real'!S:S,'Gasto Real'!$E:$E,Resumen!$E10) -> 0 | T10: =SUMIFS('Gasto Real'!T:T,'Gasto Real'!$E:$E,Resumen!$E10) -> 321 | U10: =SUM(H10:T10)*-1 -> -5819.85 | V10: =SUMIFS('Evento R'!H:H,'Evento R'!$E:$E,Resumen!$E10) -> 0 | W10: =SUMIFS('Evento R'!I:I,'Evento R'!$E:$E,Resumen!$E10) -> 0 | X10: =SUMIFS('Evento R'!J:J,'Evento R'!$E:$E,Resumen!$E10) -> 0 | Y10: =SUMIFS('Evento R'!K:K,'Evento R'!$E:$E,Resumen!$E10) -> 0 | Z10: =SUMIFS('Evento R'!L:L,'Evento R'!$E:$E,Resumen!$E10) -> 0 | AA10: =SUMIFS('Evento R'!M:M,'Evento R'!$E:$E,Resumen!$E10) -> 0 | AB10: =SUMIFS('Evento R'!N:N,'Evento R'!$E:$E,Resumen!$E10) -> 0 | AC10: =SUMIFS('Evento R'!O:O,'Evento R'!$E:$E,Resumen!$E10) -> 0 | AD10: =SUMIFS('Evento R'!P:P,'Evento R'!$E:$E,Resumen!$E10) -> 10000 | AE10: =SUMIFS('Evento R'!Q:Q,'Evento R'!$E:$E,Resumen!$E10) -> 0 | AF10: =SUM(V10:AE10)*-1 -> -10000 | AH10: =SUM(F10)+SUM(U10,AF10) -> 8038.8
A11: 46296 | B11: 46296 | C11: 46310 | D11: 1 | E11: Q14 | F11: =G11+AH10 -> 23038.8 | G11: =SUMIFS(Ingresos!H:H,Ingresos!A:A,Resumen!A11)+SUMIFS(Ingresos!I:I,Ingresos!A:A,Resumen!A11)+SUMIFS(Ingresos!K:K,Ingresos!A:A,Resumen!A11) -> 15000 | H11: =SUMIFS('Gasto Real'!H:H,'Gasto Real'!$E:$E,Resumen!$E11) -> 551.85 | I11: =SUMIFS('Gasto Real'!I:I,'Gasto Real'!$E:$E,Resumen!$E11) -> 0 | J11: =SUMIFS('Gasto Real'!J:J,'Gasto Real'!$E:$E,Resumen!$E11) -> 0 | K11: =SUMIFS('Gasto Real'!K:K,'Gasto Real'!$E:$E,Resumen!$E11) -> 0 | L11: =SUMIFS('Gasto Real'!L:L,'Gasto Real'!$E:$E,Resumen!$E11) -> 0 | M11: =SUMIFS('Gasto Real'!M:M,'Gasto Real'!$E:$E,Resumen!$E11) -> 600 | N11: =SUMIFS('Gasto Real'!N:N,'Gasto Real'!$E:$E,Resumen!$E11) -> 0 | O11: =SUMIFS('Gasto Real'!O:O,'Gasto Real'!$E:$E,Resumen!$E11) -> 3600 | P11: =SUMIFS('Gasto Real'!P:P,'Gasto Real'!$E:$E,Resumen!$E11) -> 0 | Q11: =SUMIFS('Gasto Real'!Q:Q,'Gasto Real'!$E:$E,Resumen!$E11) -> 0 | R11: =SUMIFS('Gasto Real'!R:R,'Gasto Real'!$E:$E,Resumen!$E11) -> 140 | S11: =SUMIFS('Gasto Real'!S:S,'Gasto Real'!$E:$E,Resumen!$E11) -> 140 | T11: =SUMIFS('Gasto Real'!T:T,'Gasto Real'!$E:$E,Resumen!$E11) -> 0 | U11: =SUM(H11:T11)*-1 -> -5031.85 | V11: =SUMIFS('Evento R'!H:H,'Evento R'!$E:$E,Resumen!$E11) -> 0 | W11: =SUMIFS('Evento R'!I:I,'Evento R'!$E:$E,Resumen!$E11) -> 0 | X11: =SUMIFS('Evento R'!J:J,'Evento R'!$E:$E,Resumen!$E11) -> 0 | Y11: =SUMIFS('Evento R'!K:K,'Evento R'!$E:$E,Resumen!$E11) -> 0 | Z11: =SUMIFS('Evento R'!L:L,'Evento R'!$E:$E,Resumen!$E11) -> 0 | AA11: =SUMIFS('Evento R'!M:M,'Evento R'!$E:$E,Resumen!$E11) -> 0 | AB11: =SUMIFS('Evento R'!N:N,'Evento R'!$E:$E,Resumen!$E11) -> 0 | AC11: =SUMIFS('Evento R'!O:O,'Evento R'!$E:$E,Resumen!$E11) -> 0 | AD11: =SUMIFS('Evento R'!P:P,'Evento R'!$E:$E,Resumen!$E11) -> 0 | AE11: =SUMIFS('Evento R'!Q:Q,'Evento R'!$E:$E,Resumen!$E11) -> 0 | AF11: =SUM(V11:AE11)*-1 -> 0 | AH11: =SUM(F11)+SUM(U11,AF11) -> 18006.95
A12: 46311 | B12: 46311 | C12: 46326 | D12: 1 | E12: Q15 | F12: =G12+AH11 -> 33006.95 | G12: =SUMIFS(Ingresos!H:H,Ingresos!A:A,Resumen!A12)+SUMIFS(Ingresos!I:I,Ingresos!A:A,Resumen!A12)+SUMIFS(Ingresos!K:K,Ingresos!A:A,Resumen!A12) -> 15000 | H12: =SUMIFS('Gasto Real'!H:H,'Gasto Real'!$E:$E,Resumen!$E12) -> 594.3 | I12: =SUMIFS('Gasto Real'!I:I,'Gasto Real'!$E:$E,Resumen!$E12) -> 450 | J12: =SUMIFS('Gasto Real'!J:J,'Gasto Real'!$E:$E,Resumen!$E12) -> 449 | K12: =SUMIFS('Gasto Real'!K:K,'Gasto Real'!$E:$E,Resumen!$E12) -> 239 | L12: =SUMIFS('Gasto Real'!L:L,'Gasto Real'!$E:$E,Resumen!$E12) -> 139 | M12: =SUMIFS('Gasto Real'!M:M,'Gasto Real'!$E:$E,Resumen!$E12) -> 0 | N12: =SUMIFS('Gasto Real'!N:N,'Gasto Real'!$E:$E,Resumen!$E12) -> 0 | O12: =SUMIFS('Gasto Real'!O:O,'Gasto Real'!$E:$E,Resumen!$E12) -> 3600 | P12: =SUMIFS('Gasto Real'!P:P,'Gasto Real'!$E:$E,Resumen!$E12) -> 0 | Q12: =SUMIFS('Gasto Real'!Q:Q,'Gasto Real'!$E:$E,Resumen!$E12) -> 70 | R12: =SUMIFS('Gasto Real'!R:R,'Gasto Real'!$E:$E,Resumen!$E12) -> 0 | S12: =SUMIFS('Gasto Real'!S:S,'Gasto Real'!$E:$E,Resumen!$E12) -> 0 | T12: =SUMIFS('Gasto Real'!T:T,'Gasto Real'!$E:$E,Resumen!$E12) -> 321 | U12: =SUM(H12:T12)*-1 -> -5862.3 | V12: =SUMIFS('Evento R'!H:H,'Evento R'!$E:$E,Resumen!$E12) -> 0 | W12: =SUMIFS('Evento R'!I:I,'Evento R'!$E:$E,Resumen!$E12) -> 0 | X12: =SUMIFS('Evento R'!J:J,'Evento R'!$E:$E,Resumen!$E12) -> 0 | Y12: =SUMIFS('Evento R'!K:K,'Evento R'!$E:$E,Resumen!$E12) -> 0 | Z12: =SUMIFS('Evento R'!L:L,'Evento R'!$E:$E,Resumen!$E12) -> 0 | AA12: =SUMIFS('Evento R'!M:M,'Evento R'!$E:$E,Resumen!$E12) -> 0 | AB12: =SUMIFS('Evento R'!N:N,'Evento R'!$E:$E,Resumen!$E12) -> 0 | AC12: =SUMIFS('Evento R'!O:O,'Evento R'!$E:$E,Resumen!$E12) -> 0 | AD12: =SUMIFS('Evento R'!P:P,'Evento R'!$E:$E,Resumen!$E12) -> 0 | AE12: =SUMIFS('Evento R'!Q:Q,'Evento R'!$E:$E,Resumen!$E12) -> 0 | AF12: =SUM(V12:AE12)*-1 -> 0 | AH12: =SUM(F12)+SUM(U12,AF12) -> 27144.65
A13: 46327 | B13: 46327 | C13: 46341 | D13: 1 | E13: Q16 | F13: =G13+AH12 -> 42144.65 | G13: =SUMIFS(Ingresos!H:H,Ingresos!A:A,Resumen!A13)+SUMIFS(Ingresos!I:I,Ingresos!A:A,Resumen!A13)+SUMIFS(Ingresos!K:K,Ingresos!A:A,Resumen!A13) -> 15000 | H13: =SUMIFS('Gasto Real'!H:H,'Gasto Real'!$E:$E,Resumen!$E13) -> 509.4 | I13: =SUMIFS('Gasto Real'!I:I,'Gasto Real'!$E:$E,Resumen!$E13) -> 0 | J13: =SUMIFS('Gasto Real'!J:J,'Gasto Real'!$E:$E,Resumen!$E13) -> 0 | K13: =SUMIFS('Gasto Real'!K:K,'Gasto Real'!$E:$E,Resumen!$E13) -> 0 | L13: =SUMIFS('Gasto Real'!L:L,'Gasto Real'!$E:$E,Resumen!$E13) -> 0 | M13: =SUMIFS('Gasto Real'!M:M,'Gasto Real'!$E:$E,Resumen!$E13) -> 0 | N13: =SUMIFS('Gasto Real'!N:N,'Gasto Real'!$E:$E,Resumen!$E13) -> 1200 | O13: =SUMIFS('Gasto Real'!O:O,'Gasto Real'!$E:$E,Resumen!$E13) -> 3600 | P13: =SUMIFS('Gasto Real'!P:P,'Gasto Real'!$E:$E,Resumen!$E13) -> 0 | Q13: =SUMIFS('Gasto Real'!Q:Q,'Gasto Real'!$E:$E,Resumen!$E13) -> 0 | R13: =SUMIFS('Gasto Real'!R:R,'Gasto Real'!$E:$E,Resumen!$E13) -> 70 | S13: =SUMIFS('Gasto Real'!S:S,'Gasto Real'!$E:$E,Resumen!$E13) -> 70 | T13: =SUMIFS('Gasto Real'!T:T,'Gasto Real'!$E:$E,Resumen!$E13) -> 0 | U13: =SUM(H13:T13)*-1 -> -5449.4 | V13: =SUMIFS('Evento R'!H:H,'Evento R'!$E:$E,Resumen!$E13) -> 0 | W13: =SUMIFS('Evento R'!I:I,'Evento R'!$E:$E,Resumen!$E13) -> 0 | X13: =SUMIFS('Evento R'!J:J,'Evento R'!$E:$E,Resumen!$E13) -> 0 | Y13: =SUMIFS('Evento R'!K:K,'Evento R'!$E:$E,Resumen!$E13) -> 0 | Z13: =SUMIFS('Evento R'!L:L,'Evento R'!$E:$E,Resumen!$E13) -> 0 | AA13: =SUMIFS('Evento R'!M:M,'Evento R'!$E:$E,Resumen!$E13) -> 0 | AB13: =SUMIFS('Evento R'!N:N,'Evento R'!$E:$E,Resumen!$E13) -> 0 | AC13: =SUMIFS('Evento R'!O:O,'Evento R'!$E:$E,Resumen!$E13) -> 0 | AD13: =SUMIFS('Evento R'!P:P,'Evento R'!$E:$E,Resumen!$E13) -> 0 | AE13: =SUMIFS('Evento R'!Q:Q,'Evento R'!$E:$E,Resumen!$E13) -> 0 | AF13: =SUM(V13:AE13)*-1 -> 0 | AH13: =SUM(F13)+SUM(U13,AF13) -> 36695.25
A14: 46342 | B14: 46342 | C14: 46356 | D14: 1 | E14: Q17 | F14: =G14+AH13 -> 51695.25 | G14: =SUMIFS(Ingresos!H:H,Ingresos!A:A,Resumen!A14)+SUMIFS(Ingresos!I:I,Ingresos!A:A,Resumen!A14)+SUMIFS(Ingresos!K:K,Ingresos!A:A,Resumen!A14) -> 15000 | H14: =SUMIFS('Gasto Real'!H:H,'Gasto Real'!$E:$E,Resumen!$E14) -> 551.85 | I14: =SUMIFS('Gasto Real'!I:I,'Gasto Real'!$E:$E,Resumen!$E14) -> 450 | J14: =SUMIFS('Gasto Real'!J:J,'Gasto Real'!$E:$E,Resumen!$E14) -> 449 | K14: =SUMIFS('Gasto Real'!K:K,'Gasto Real'!$E:$E,Resumen!$E14) -> 239 | L14: =SUMIFS('Gasto Real'!L:L,'Gasto Real'!$E:$E,Resumen!$E14) -> 139 | M14: =SUMIFS('Gasto Real'!M:M,'Gasto Real'!$E:$E,Resumen!$E14) -> 0 | N14: =SUMIFS('Gasto Real'!N:N,'Gasto Real'!$E:$E,Resumen!$E14) -> 0 | O14: =SUMIFS('Gasto Real'!O:O,'Gasto Real'!$E:$E,Resumen!$E14) -> 3600 | P14: =SUMIFS('Gasto Real'!P:P,'Gasto Real'!$E:$E,Resumen!$E14) -> 0 | Q14: =SUMIFS('Gasto Real'!Q:Q,'Gasto Real'!$E:$E,Resumen!$E14) -> 70 | R14: =SUMIFS('Gasto Real'!R:R,'Gasto Real'!$E:$E,Resumen!$E14) -> 0 | S14: =SUMIFS('Gasto Real'!S:S,'Gasto Real'!$E:$E,Resumen!$E14) -> 0 | T14: =SUMIFS('Gasto Real'!T:T,'Gasto Real'!$E:$E,Resumen!$E14) -> 321 | U14: =SUM(H14:T14)*-1 -> -5819.85 | V14: =SUMIFS('Evento R'!H:H,'Evento R'!$E:$E,Resumen!$E14) -> 0 | W14: =SUMIFS('Evento R'!I:I,'Evento R'!$E:$E,Resumen!$E14) -> 0 | X14: =SUMIFS('Evento R'!J:J,'Evento R'!$E:$E,Resumen!$E14) -> 0 | Y14: =SUMIFS('Evento R'!K:K,'Evento R'!$E:$E,Resumen!$E14) -> 0 | Z14: =SUMIFS('Evento R'!L:L,'Evento R'!$E:$E,Resumen!$E14) -> 0 | AA14: =SUMIFS('Evento R'!M:M,'Evento R'!$E:$E,Resumen!$E14) -> 5000 | AB14: =SUMIFS('Evento R'!N:N,'Evento R'!$E:$E,Resumen!$E14) -> 0 | AC14: =SUMIFS('Evento R'!O:O,'Evento R'!$E:$E,Resumen!$E14) -> 0 | AD14: =SUMIFS('Evento R'!P:P,'Evento R'!$E:$E,Resumen!$E14) -> 0 | AE14: =SUMIFS('Evento R'!Q:Q,'Evento R'!$E:$E,Resumen!$E14) -> 0 | AF14: =SUM(V14:AE14)*-1 -> -5000 | AH14: =SUM(F14)+SUM(U14,AF14) -> 40875.4
A15: 46357 | B15: 46357 | C15: 46371 | D15: 1 | E15: Q18 | F15: =G15+AH14 -> 55875.4 | G15: =SUMIFS(Ingresos!H:H,Ingresos!A:A,Resumen!A15)+SUMIFS(Ingresos!I:I,Ingresos!A:A,Resumen!A15)+SUMIFS(Ingresos!K:K,Ingresos!A:A,Resumen!A15) -> 15000 | H15: =SUMIFS('Gasto Real'!H:H,'Gasto Real'!$E:$E,Resumen!$E15) -> 551.85 | I15: =SUMIFS('Gasto Real'!I:I,'Gasto Real'!$E:$E,Resumen!$E15) -> 0 | J15: =SUMIFS('Gasto Real'!J:J,'Gasto Real'!$E:$E,Resumen!$E15) -> 0 | K15: =SUMIFS('Gasto Real'!K:K,'Gasto Real'!$E:$E,Resumen!$E15) -> 0 | L15: =SUMIFS('Gasto Real'!L:L,'Gasto Real'!$E:$E,Resumen!$E15) -> 0 | M15: =SUMIFS('Gasto Real'!M:M,'Gasto Real'!$E:$E,Resumen!$E15) -> 600 | N15: =SUMIFS('Gasto Real'!N:N,'Gasto Real'!$E:$E,Resumen!$E15) -> 0 | O15: =SUMIFS('Gasto Real'!O:O,'Gasto Real'!$E:$E,Resumen!$E15) -> 3600 | P15: =SUMIFS('Gasto Real'!P:P,'Gasto Real'!$E:$E,Resumen!$E15) -> 0 | Q15: =SUMIFS('Gasto Real'!Q:Q,'Gasto Real'!$E:$E,Resumen!$E15) -> 0 | R15: =SUMIFS('Gasto Real'!R:R,'Gasto Real'!$E:$E,Resumen!$E15) -> 140 | S15: =SUMIFS('Gasto Real'!S:S,'Gasto Real'!$E:$E,Resumen!$E15) -> 140 | T15: =SUMIFS('Gasto Real'!T:T,'Gasto Real'!$E:$E,Resumen!$E15) -> 0 | U15: =SUM(H15:T15)*-1 -> -5031.85 | V15: =SUMIFS('Evento R'!H:H,'Evento R'!$E:$E,Resumen!$E15) -> 0 | W15: =SUMIFS('Evento R'!I:I,'Evento R'!$E:$E,Resumen!$E15) -> 0 | X15: =SUMIFS('Evento R'!J:J,'Evento R'!$E:$E,Resumen!$E15) -> 0 | Y15: =SUMIFS('Evento R'!K:K,'Evento R'!$E:$E,Resumen!$E15) -> 0 | Z15: =SUMIFS('Evento R'!L:L,'Evento R'!$E:$E,Resumen!$E15) -> 0 | AA15: =SUMIFS('Evento R'!M:M,'Evento R'!$E:$E,Resumen!$E15) -> 5000 | AB15: =SUMIFS('Evento R'!N:N,'Evento R'!$E:$E,Resumen!$E15) -> 0 | AC15: =SUMIFS('Evento R'!O:O,'Evento R'!$E:$E,Resumen!$E15) -> 0 | AD15: =SUMIFS('Evento R'!P:P,'Evento R'!$E:$E,Resumen!$E15) -> 0 | AE15: =SUMIFS('Evento R'!Q:Q,'Evento R'!$E:$E,Resumen!$E15) -> 0 | AF15: =SUM(V15:AE15)*-1 -> -5000 | AH15: =SUM(F15)+SUM(U15,AF15) -> 45843.55
A16: 46372 | B16: 46372 | C16: 46143 | D16: 1 | E16: Q19 | F16: =G16+AH15 -> 60843.55 | G16: =SUMIFS(Ingresos!H:H,Ingresos!A:A,Resumen!A16)+SUMIFS(Ingresos!I:I,Ingresos!A:A,Resumen!A16)+SUMIFS(Ingresos!K:K,Ingresos!A:A,Resumen!A16) -> 15000 | H16: =SUMIFS('Gasto Real'!H:H,'Gasto Real'!$E:$E,Resumen!$E16) -> 594.3 | I16: =SUMIFS('Gasto Real'!I:I,'Gasto Real'!$E:$E,Resumen!$E16) -> 450 | J16: =SUMIFS('Gasto Real'!J:J,'Gasto Real'!$E:$E,Resumen!$E16) -> 449 | K16: =SUMIFS('Gasto Real'!K:K,'Gasto Real'!$E:$E,Resumen!$E16) -> 239 | L16: =SUMIFS('Gasto Real'!L:L,'Gasto Real'!$E:$E,Resumen!$E16) -> 139 | M16: =SUMIFS('Gasto Real'!M:M,'Gasto Real'!$E:$E,Resumen!$E16) -> 0 | N16: =SUMIFS('Gasto Real'!N:N,'Gasto Real'!$E:$E,Resumen!$E16) -> 0 | O16: =SUMIFS('Gasto Real'!O:O,'Gasto Real'!$E:$E,Resumen!$E16) -> 3600 | P16: =SUMIFS('Gasto Real'!P:P,'Gasto Real'!$E:$E,Resumen!$E16) -> 0 | Q16: =SUMIFS('Gasto Real'!Q:Q,'Gasto Real'!$E:$E,Resumen!$E16) -> 70 | R16: =SUMIFS('Gasto Real'!R:R,'Gasto Real'!$E:$E,Resumen!$E16) -> 0 | S16: =SUMIFS('Gasto Real'!S:S,'Gasto Real'!$E:$E,Resumen!$E16) -> 0 | T16: =SUMIFS('Gasto Real'!T:T,'Gasto Real'!$E:$E,Resumen!$E16) -> 321 | U16: =SUM(H16:T16)*-1 -> -5862.3 | V16: =SUMIFS('Evento R'!H:H,'Evento R'!$E:$E,Resumen!$E16) -> 0 | W16: =SUMIFS('Evento R'!I:I,'Evento R'!$E:$E,Resumen!$E16) -> 0 | X16: =SUMIFS('Evento R'!J:J,'Evento R'!$E:$E,Resumen!$E16) -> 0 | Y16: =SUMIFS('Evento R'!K:K,'Evento R'!$E:$E,Resumen!$E16) -> 0 | Z16: =SUMIFS('Evento R'!L:L,'Evento R'!$E:$E,Resumen!$E16) -> 0 | AA16: =SUMIFS('Evento R'!M:M,'Evento R'!$E:$E,Resumen!$E16) -> 5000 | AB16: =SUMIFS('Evento R'!N:N,'Evento R'!$E:$E,Resumen!$E16) -> 0 | AC16: =SUMIFS('Evento R'!O:O,'Evento R'!$E:$E,Resumen!$E16) -> 0 | AD16: =SUMIFS('Evento R'!P:P,'Evento R'!$E:$E,Resumen!$E16) -> 0 | AE16: =SUMIFS('Evento R'!Q:Q,'Evento R'!$E:$E,Resumen!$E16) -> 0 | AF16: =SUM(V16:AE16)*-1 -> -5000 | AH16: =SUM(F16)+SUM(U16,AF16) -> 49981.25
A17: 46376 | B17: 46376 | C17: 46376 | D17: 1 | E17: Q18.5 | F17: =G17+AH16 -> 49981.25 | G17: =SUMIFS(Ingresos!H:H,Ingresos!A:A,Resumen!A17)+SUMIFS(Ingresos!I:I,Ingresos!A:A,Resumen!A17)+SUMIFS(Ingresos!K:K,Ingresos!A:A,Resumen!A17) -> 0 | H17: =SUMIFS('Gasto Real'!H:H,'Gasto Real'!$E:$E,Resumen!$E17) -> 0 | I17: =SUMIFS('Gasto Real'!I:I,'Gasto Real'!$E:$E,Resumen!$E17) -> 0 | J17: =SUMIFS('Gasto Real'!J:J,'Gasto Real'!$E:$E,Resumen!$E17) -> 0 | K17: =SUMIFS('Gasto Real'!K:K,'Gasto Real'!$E:$E,Resumen!$E17) -> 0 | L17: =SUMIFS('Gasto Real'!L:L,'Gasto Real'!$E:$E,Resumen!$E17) -> 0 | M17: =SUMIFS('Gasto Real'!M:M,'Gasto Real'!$E:$E,Resumen!$E17) -> 0 | N17: =SUMIFS('Gasto Real'!N:N,'Gasto Real'!$E:$E,Resumen!$E17) -> 0 | O17: =SUMIFS('Gasto Real'!O:O,'Gasto Real'!$E:$E,Resumen!$E17) -> 1800 | P17: =SUMIFS('Gasto Real'!P:P,'Gasto Real'!$E:$E,Resumen!$E17) -> 0 | Q17: =SUMIFS('Gasto Real'!Q:Q,'Gasto Real'!$E:$E,Resumen!$E17) -> 0 | R17: =SUMIFS('Gasto Real'!R:R,'Gasto Real'!$E:$E,Resumen!$E17) -> 70 | S17: =SUMIFS('Gasto Real'!S:S,'Gasto Real'!$E:$E,Resumen!$E17) -> 70 | T17: =SUMIFS('Gasto Real'!T:T,'Gasto Real'!$E:$E,Resumen!$E17) -> 0 | U17: =SUM(H17:T17)*-1 -> -1940 | V17: =SUMIFS('Evento R'!H:H,'Evento R'!$E:$E,Resumen!$E17) -> 0 | W17: =SUMIFS('Evento R'!I:I,'Evento R'!$E:$E,Resumen!$E17) -> 0 | X17: =SUMIFS('Evento R'!J:J,'Evento R'!$E:$E,Resumen!$E17) -> 0 | Y17: =SUMIFS('Evento R'!K:K,'Evento R'!$E:$E,Resumen!$E17) -> 0 | Z17: =SUMIFS('Evento R'!L:L,'Evento R'!$E:$E,Resumen!$E17) -> 0 | AA17: =SUMIFS('Evento R'!M:M,'Evento R'!$E:$E,Resumen!$E17) -> 0 | AB17: =SUMIFS('Evento R'!N:N,'Evento R'!$E:$E,Resumen!$E17) -> 0 | AC17: =SUMIFS('Evento R'!O:O,'Evento R'!$E:$E,Resumen!$E17) -> 0 | AD17: =SUMIFS('Evento R'!P:P,'Evento R'!$E:$E,Resumen!$E17) -> 0 | AE17: =SUMIFS('Evento R'!Q:Q,'Evento R'!$E:$E,Resumen!$E17) -> 0 | AF17: =SUM(V17:AE17)*-1 -> 0 | AH17: =SUM(F17)+SUM(U17,AF17) -> 48041.25
